<mujoco model="NaoH25V50">
    <compiler angle="radian" meshdir="./nao_meshes/meshes/V40/"/>
    <option integrator="RK4"/>
    <default>
    	<joint  armature="1" damping="1"/>
    </default>
    <size njmax="500" nconmax="100" />
    <asset>
    	<mesh name="RShoulderPitch_0.10" file="RShoulderPitch_0.10.stl" scale="0.1 0.1 0.1" />
        <mesh name="RShoulderRoll_0.10" file="RShoulderRoll_0.10.stl" scale="0.1 0.1 0.1" />
        <mesh name="RElbowRoll_0.10" file="RElbowRoll_0.10.stl" scale="0.1 0.1 0.1" />
        <mesh name="RWristYaw_0.10" file="RWristYaw_0.10.stl" scale="0.1 0.1 0.1" />
        <mesh name="RFinger21_0.10" file="RFinger21_0.10.stl" scale="0.1 0.1 0.1" />
        <mesh name="RFinger22_0.10" file="RFinger22_0.10.stl" scale="0.1 0.1 0.1" />
        <mesh name="RFinger23_0.10" file="RFinger23_0.10.stl" scale="0.1 0.1 0.1" />
        <mesh name="RFinger11_0.10" file="RFinger11_0.10.stl" scale="0.1 0.1 0.1" />
        <mesh name="RFinger12_0.10" file="RFinger12_0.10.stl" scale="0.1 0.1 0.1" />
        <mesh name="RFinger13_0.10" file="RFinger13_0.10.stl" scale="0.1 0.1 0.1" />
        <mesh name="RThumb1_0.10" file="RThumb1_0.10.stl" scale="0.1 0.1 0.1" />
        <mesh name="RThumb2_0.10" file="RThumb2_0.10.stl" scale="0.1 0.1 0.1" />
        <texture builtin="checker" height="100" name="texplane" rgb1="0 0 0" rgb2="0.8 0.8 0.8" type="2d" width="100"/>
        <material name="MatPlane" reflectance="0.5" shininess="1" specular="1" texrepeat="60 60" texture="texplane"/>
    </asset>

	<worldbody>
        <geom contype="1" conaffinity="0" condim="3" friction="1 .1 .1" material="MatPlane" name="floor" pos="0 0 -0.335" rgba="0.8 0.9 0.8 1" size="20 20 0.125" type="plane"/>

        
			<site name="target" pos="0.125 0.125 0.125" size="0.01 0.01 0.01" rgba="1 0 0 1"></site>
        <body name="RShoulder" pos="0 -0.098 0.1" quat="1 0 1 0">
                <inertial pos="-0.0146753 0.0178377 0.000381054" quat="0.611486 -0.00891285 -0.0112889 0.791124" mass="0.183785" diaginertia="7.45353e-05 5.40081e-05 2.59944e-05" />
                <joint name="RShoulderPitch" pos="0 0 0" axis="0 1 0" limited="true" range="-2.08567 2.08567" />
                <geom contype="2" conaffinity="1" type="mesh" rgba="0.8 0.4 0.9 1" mesh="RShoulderPitch_0.10" />
                <body name="RBicep" pos="0 0 0">
                    <inertial pos="0.0213201 -0.00466808 0.0004386" quat="0.527557 0.52235 0.47264 0.474811" mass="1.7996" diaginertia="0.00363268 0.00337871 0.000658873" />
                    <joint name="RShoulderRoll" pos="0 0 0" axis="0 0 1" limited="true" range="-1.32645 0.314159" />
                    <geom contype="2" conaffinity="1" type="mesh" rgba="0.3 0.1 0.6 1" mesh="RShoulderRoll_0.10" />
                    <body name="RElbow" pos="0.105 -0.015 0">
                        <inertial pos="-0.02744 0 -0.00014" quat="-0.000545392 0.711779 -0.000696018 0.702403" mass="0.395499" diaginertia="0.000168578 0.000162384 3.41143e-05" />
                        <joint name="RElbowYaw" pos="0 0 0" axis="1 0 0" limited="true" range="-2.08567 2.08567" />
                        <body name="RForeArm" pos="0 0 0">
                            <inertial pos="0.0235942 -0.00369779 0.00274973" quat="0.397369 0.35311 0.66416 0.525645" mass="0.455913" diaginertia="0.000171173 0.000151629 0.000108766" />
                            <joint name="RElbowRoll" pos="0 0 0" axis="0 0 1" limited="true" range="0.0349066 1.54462" />
                            <geom contype="4" conaffinity="1" type="mesh" rgba="0.8 0.2 1 1" mesh="RElbowRoll_0.10" />
                            <body name="r_wrist" pos="0.05595 0 0">
                                <inertial pos="0.0432841 -3.00946e-05 0.00454347" quat="0.0130028 0.518963 0.00333335 0.854691" mass="0.93576" diaginertia="0.000578664 0.000517583 0.000351545" />
                                <joint name="RWristYaw" pos="0 0 0" axis="1 0 0" limited="true" range="-1.82387 1.82387" />
                                <geom contype="4" conaffinity="3" type="mesh" rgba="0.1 0.4 0.6 1" mesh="RWristYaw_0.10" />
                                <body name="r_gripper" pos="0.05775 0 -0.01213">
                                    <inertial pos="0 0 0" mass="1.22011e-05" diaginertia="6.7106e-09 6.7106e-09 6.7106e-09" />
                                    <joint name="RHand" pos="0 0 0" axis="1 0 0" limited="true" range="0 1" />
                                </body>
                                <body name="RHandTouchRight_frame" pos="0.035 -0.025 0.0035" quat="0.707105 0 0 -0.707108">
                                    <inertial pos="0.035 -0.025 0.0035" quat="0.707105 0 0 -0.707108" mass="0" diaginertia="0 0 0" />
                                </body>
                                <body name="RHandTouchBack_frame" pos="0.038 0 0.025" quat="-0.707108 1.87637e-06 0.707105 1.87637e-06">
                                    <inertial pos="0.038 0 0.025" quat="-0.707108 1.87637e-06 0.707105 1.87637e-06" mass="0" diaginertia="0 0 0" />
                                </body>
                                <body name="RHandTouchLeft_frame" pos="0.032 0.025 0.003" quat="0.707105 0 0 0.707108">
                                    <inertial pos="0.032 0.025 0.003" quat="0.707105 0 0 0.707108" mass="0" diaginertia="0 0 0" />
                                </body>
                                <body name="RFinger21_link" pos="0.06907 -0.01157 -0.00304" quat="0.672286 0.564114 0.308141 -0.367227">
                                    <inertial pos="0.00863736 0.000185977 1.64388e-05" quat="-0.0910756 0.633824 -0.0291972 0.767541" mass="0.0093394" diaginertia="2.89187e-07 2.07156e-07 1.88181e-07" />
                                    <joint name="RFinger21" pos="0 0 0" axis="0 0 1" />
                                    <geom contype="4" conaffinity="3" type="mesh" rgba="0.1 0.1 0.1 0.4" mesh="RFinger21_0.10" />
                                    <body name="RFinger22_link" pos="0.01436 0 0" quat="0.877607 0 0 -0.479381">
                                        <inertial pos="0.00844989 -0.000471502 0.000379654" quat="-0.11611 0.630939 -0.00405049 0.767084" mass="0.00931936" diaginertia="2.89039e-07 2.07549e-07 1.86708e-07" />
                                        <joint name="RFinger22" pos="0 0 0" axis="0 0 1" />
                                        <geom contype="4" conaffinity="3" type="mesh" rgba="0.1 0.1 0.1 0.4" mesh="RFinger22_0.10" />
                                        <body name="RFinger23_link" pos="0.01436 0 0" quat="0.877607 0 0 -0.479381">
                                            <inertial pos="0.00854807 -0.000314659 0.00014057" quat="-0.0663958 0.707447 -0.0375616 0.702638" mass="0.00911458" diaginertia="2.88584e-07 2.20008e-07 1.65953e-07" />
                                            <joint name="RFinger23" pos="0 0 0" axis="0 0 1" />
                                            <geom contype="4" conaffinity="3" type="mesh" rgba="0.1 0.1 0.1 0.4" mesh="RFinger23_0.10" />
                                        </body>
                                    </body>
                                </body>
                                <body name="RFinger11_link" pos="0.06907 0.01157 -0.00304" quat="0.564115 0.672285 0.367228 -0.30814">
                                    <inertial pos="0.00903321 -0.000223157 0.000206259" quat="0.00825309 0.642265 0.118529 0.757217" mass="0.00926401" diaginertia="2.85933e-07 2.0779e-07 1.82763e-07" />
                                    <joint name="RFinger11" pos="0 0 0" axis="0 0 1" />
                                    <geom contype="4" conaffinity="3" type="mesh" rgba="0.1 0.1 0.1 0.4" mesh="RFinger11_0.10" />
                                    <body name="RFinger12_link" pos="0.01436 0 0" quat="0.877607 0 0 -0.479381">
                                        <inertial pos="0.00740736 -4.2145e-05 3.50086e-05" quat="0.018982 0.639915 0.106374 0.760811" mass="0.00934554" diaginertia="2.89434e-07 2.07315e-07 1.88431e-07" />
                                        <joint name="RFinger12" pos="0 0 0" axis="0 0 1" />
                                        <geom contype="4" conaffinity="3" type="mesh" rgba="0.1 0.1 0.1 0.4" mesh="RFinger12_0.10" />
                                        <body name="RFinger13_link" pos="0.01436 0 0" quat="0.877607 0 0 -0.479381">
                                            <inertial pos="0.00824432 3.0634e-05 -9.09988e-05" quat="0.0769785 0.705516 0.0821836 0.699691" mass="0.00899706" diaginertia="2.80311e-07 2.13423e-07 1.63303e-07" />
                                            <joint name="RFinger13" pos="0 0 0" axis="0 0 1" />
                                            <geom contype="4" conaffinity="3" type="mesh" rgba="0.1 0.1 0.1 0.4" mesh="RFinger13_0.10" />
                                        </body>
                                    </body>
                                </body>
                                <body name="RThumb1_link" pos="0.04895 0 -0.02638" quat="0.706908 -0.70691 0.0167209 0.016721">
                                    <inertial pos="0.00605392 5.45792e-05 -0.00555008" quat="0.988351 -0.0944312 -0.118218 -0.0164253" mass="0.00933258" diaginertia="2.88099e-07 2.07093e-07 1.87599e-07" />
                                    <joint name="RThumb1" pos="0 0 0" axis="0 0 1" />
                                    <geom contype="4" conaffinity="3" type="mesh" rgba="0.1 0.1 0.1 0.4" mesh="RThumb1_0.10" />
                                    <body name="RThumb2_link" pos="0.01436 0 0" quat="0.877607 0 0 -0.479381">
                                        <inertial pos="0.00294165 -0.000445346 -0.00797671" quat="0.962667 0.0074404 -0.270146 0.0154311" mass="0.00904133" diaginertia="2.84681e-07 2.16067e-07 1.64498e-07" />
                                        <joint name="RThumb2" pos="0 0 0" axis="0 0 1" />
                                        <geom contype="4" conaffinity="3" type="mesh" rgba="0.1 0.1 0.1 0.4" mesh="RThumb2_0.10" />
                                    </body>
                                </body>
                				<site name="reacher" pos="0.075 0 -0.001" size="0.01 0.01 0.01" rgba="1 1 1 1"></site>
                            </body>
                        </body>
                    </body>
                </body>
            </body>
        
    </worldbody>
    <actuator>
        
        <position ctrllimited="true" ctrlrange="-1.0 1.0" gear="200.0" joint="RShoulderPitch" kp="1"/>
        <position ctrllimited="true" ctrlrange="-1.0 1.0" gear="200.0" joint="RShoulderRoll" kp="1"/>
        <position ctrllimited="true" ctrlrange="-1.0 1.0" gear="200.0" joint="RElbowYaw"/>
        <position ctrllimited="true" ctrlrange="-1.0 1.0" gear="200.0" joint="RElbowRoll"/>

        
    </actuator>
</mujoco>    