<mujoco model="NaoH25V50">
    <compiler angle="radian" meshdir="./nao_meshes/meshes/V40/"/>
    <option integrator="RK4"/>

    <default>
        <joint  armature="1" damping="5"/>
    </default>
    <size njmax="500" nconmax="100" />
    <asset>
        <mesh name="RShoulderPitch_0.10" file="RShoulderPitch_0.10.stl" scale="0.1 0.1 0.1" />
        <mesh name="RShoulderRoll_0.10" file="RShoulderRoll_0.10.stl" scale="0.1 0.1 0.1" />
        <mesh name="RElbowRoll_0.10" file="RElbowRoll_0.10.stl" scale="0.1 0.1 0.1" />
        <mesh name="RWristYaw_0.10" file="RWristYaw_0.10.stl" scale="0.1 0.1 0.1" />
        <mesh name="RFinger21_0.10" file="RFinger21_0.10.stl" scale="0.1 0.1 0.1" />
        <mesh name="RFinger22_0.10" file="RFinger22_0.10.stl" scale="0.1 0.1 0.1" />
        <mesh name="RFinger23_0.10" file="RFinger23_0.10.stl" scale="0.1 0.1 0.1" />
        <mesh name="RFinger11_0.10" file="RFinger11_0.10.stl" scale="0.1 0.1 0.1" />
        <mesh name="RFinger12_0.10" file="RFinger12_0.10.stl" scale="0.1 0.1 0.1" />
        <mesh name="RFinger13_0.10" file="RFinger13_0.10.stl" scale="0.1 0.1 0.1" />
        <mesh name="RThumb1_0.10" file="RThumb1_0.10.stl" scale="0.1 0.1 0.1" />
        <mesh name="RThumb2_0.10" file="RThumb2_0.10.stl" scale="0.1 0.1 0.1" />
        <texture builtin="checker" height="100" name="texplane" rgb1="0 0 0" rgb2="0.8 0.8 0.8" type="2d" width="100"/>
        <material name="MatPlane" reflectance="0.5" shininess="1" specular="1" texrepeat="60 60" texture="texplane"/>
    </asset>

    <worldbody>
                <geom contype="1" conaffinity="1" condim="3" friction="1 .1 .1" material="MatPlane" name="floor" pos="0 0 -0.335" rgba="0.8 0.9 0.8 1" size="20 20 0.125" type="plane"/>

                
           

                <body name="RBicep" pos="0 0 0" quat="1 0 1 0">
                    <!-- <joint name="RShoulderZ" type="slide" axis="0 0 1"/> -->
                    <inertial pos="0.0213201 -0.00466808 0.0004386" quat="0.527557 0.52235 0.47264 0.474811" mass="1.7996" diaginertia="0.00363268 0.00337871 0.000658873" />
                    <joint name="RShoulderRoll" pos="0 0 0" axis="0 1 0"  limited="true" range="0 4" type="hinge"/>
                    <joint name="RShoulderPitch" pos="0 0 0" axis="0 0 1" limited="true" range="0 2.4" type="hinge"/>
                    <geom contype="2" conaffinity="1" type="mesh" rgba="0.3 0.1 0.6 1" mesh="RShoulderRoll_0.10" />
                    
        <body name="RElbow" pos="0.105 -0.015 0">
                        <inertial pos="-0.02744 0 -0.00014" quat="-0.000545392 0.711779 -0.000696018 0.702403" mass="0.395499" diaginertia="0.000168578 0.000162384 3.41143e-05" />
                        <joint name="RElbowYaw" pos="0 0 0" axis="0 1 0" type="hinge" limited="true" range="0 2.3" />
                        <body name="RForeArm" pos="0 0 0">
                            <inertial pos="0.0235942 -0.00369779 0.00274973" quat="0.397369 0.35311 0.66416 0.525645" mass="0.455913" diaginertia="0.000171173 0.000151629 0.000108766" />
                            <joint name="RElbowRoll" pos="0 0 0" axis="0 0 1" limited="true" range="-2.3 0" type="hinge" />
                            <geom contype="2" conaffinity="1" type="mesh" rgba="0.8 0.2 1 1" mesh="RElbowRoll_0.10" />


                            <body name="r_wrist" pos="0.05595 0 0">
                                <inertial pos="0.0432841 -3.00946e-05 0.00454347" quat="0.0130028 0.518963 0.00333335 0.854691" mass="0.93576" diaginertia="0.000578664 0.000517583 0.000351545" />
                                <joint name="RWristYaw" pos="0 0 0" axis="1 0 0" />
                                <geom contype="2" conaffinity="1" type="mesh" rgba="0.1 0.4 0.6 1" mesh="RWristYaw_0.10" />
                                <body name="r_gripper" pos="0.05775 0 -0.01213">
                                    <inertial pos="0 0 0" mass="1.22011e-05" diaginertia="6.7106e-09 6.7106e-09 6.7106e-09" />
                                    
                                </body>
                                <body name="RHandTouchRight_frame" pos="0.035 -0.025 0.0035" quat="0.707105 0 0 -0.707108">
                                    <inertial pos="0.035 -0.025 0.0035" quat="0.707105 0 0 -0.707108" mass="0" diaginertia="0 0 0" />
                                </body>
                                <body name="RHandTouchBack_frame" pos="0.038 0 0.025" quat="-0.707108 1.87637e-06 0.707105 1.87637e-06">
                                    <site name="reacher" pos="-0.03 0.009 -0.03" size="0.01 0.01 0.01" rgba="1 1 1 1"></site>
                                    <inertial pos="0.038 0 0.025" quat="-0.707108 1.87637e-06 0.707105 1.87637e-06" mass="0" diaginertia="0 0 0" />
                                </body>
                                <body name="RHandTouchLeft_frame" pos="0.032 0.025 0.003" quat="0.707105 0 0 0.707108">

                                
                            
                                    <inertial pos="0.032 0.025 0.003" quat="0.707105 0 0 0.707108" mass="0" diaginertia="0 0 0" />
                                </body>
                            </body>
                        </body>
                    </body>
                </body>

                
         <site name="target" pos="0.125 0.125 0.125" size="0.01 0.01 0.01" rgba="1 0 0 1"></site>
       
    </worldbody>
    <actuator>
        
        <position  ctrllimited="true" ctrlrange="0 2.4" gear="200.0" joint="RShoulderPitch" />
        <position  ctrllimited="true" ctrlrange="0 4" gear="200.0" joint="RShoulderRoll" />
        <position  ctrllimited="true" ctrlrange="0 2.3" gear="200.0" joint="RElbowYaw" />
        <position  ctrllimited="true" ctrlrange="-2.3 0" gear="200.0" joint="RElbowRoll" />
        <!-- <position   gear="200.0" joint="RWristYaw" />
        <position   gear="200.0" joint="RHand" />
 -->
        <!-- <position  gear="200.0" joint="RShoulderZ" /> -->
        
    </actuator>
</mujoco>    


